#define MsTestUnitTests
#if MsTestUnitTests
namespace Microshaoft
{
    using Microsoft.VisualStudio.TestTools.UnitTesting;
    using System;
    //using static Microsoft.QualityTools.Testing.Fakes.FakesDelegates;

    public static class AssertHelper
    {
        private const string _beginSpliterLineOfMessageBlock   = "<<<<<<<<<<<<<<<<<<<<<<<<<<";
        private const string _endSpliterLineOfMessageBlock     = ">>>>>>>>>>>>>>>>>>>>>>>>>>";

        private static Exception drillDownInnerException
                                            (
                                                this Exception @this
                                                , Func<Exception, bool> onProcessFunc = null!
                                                , bool needDrillDownInnerException = true
                                            )
        {
            var result = @this;
            while (result != null)
            {
                if (onProcessFunc != null)
                {
                    bool @return = onProcessFunc(result);
                    if (@return)
                    {
                        break;
                    }
                }
                if (!needDrillDownInnerException)
                {
                    break;
                }
                result = result.InnerException;
            }
            return result!;

        }

        private static void processExpectedExceptionMessage
                                    (
                                        Exception exception
                                        , string expectedExceptionMessage = null!
                                    )
        {
            if
                (
                    !string
                        .IsNullOrEmpty
                                (
                                    expectedExceptionMessage
                                )
                )
            {
                Assert
                    .IsTrue
                        (
                            string.Compare(expectedExceptionMessage, exception.Message, true) == 0
                            , $@"Expected exception of type {exception.GetType()} with a message of ""{expectedExceptionMessage}"" but exception with message of ""{exception.Message}"" was thrown instead.
The caught actual exception as below:
{_beginSpliterLineOfMessageBlock}
{exception}
{_endSpliterLineOfMessageBlock}
"
                        );
            }
        }

        public static void Throws
                                <TExpectedException>
                                    (
                                        this Assert @this
                                        , Action action
                                        , string expectedExceptionMessage = null!
                                        , Action<TExpectedException> onProcessAction = null!
                                        , bool needDrillDownInnerExceptions = true
                                    )
                                        where TExpectedException : Exception
        {
            Action<Exception> actionExceptionProcess = null!;
            if (onProcessAction != null)
            {
                actionExceptionProcess = (e) =>
                {
                    onProcessAction((TExpectedException) e);
                };
            }
            Throws
                (
                    @this
                    , action
                    , typeof(TExpectedException)
                    , expectedExceptionMessage
                    , actionExceptionProcess
                    , needDrillDownInnerExceptions
                );
        }

        public static void Throws
                                (
                                    this Assert @this
                                    , Action action
                                    , Type expectedExceptionType
                                    , string expectedExceptionMessage = null!
                                    , Action<Exception> onProcessAction = null!
                                    , bool needDrillDownInnerExceptions = true
                                )
        {
            Exception caughtException = null!;
            Exception caughtExpectedException = null!;
            var foundCaughtExpectedException = false;

            void drillDownInnerExceptionProcess(Exception e)
            {
                caughtExpectedException = e
                                            .drillDownInnerException
                                                (
                                                    (ee) =>
                                                    {
                                                        foundCaughtExpectedException =
                                                            (
                                                                ee.GetType() == expectedExceptionType
                                                                &&
                                                                (
                                                                    string
                                                                        .Compare
                                                                            (
                                                                                expectedExceptionMessage
                                                                                , ee.Message
                                                                                , true
                                                                            ) == 0
                                                                    ||
                                                                    string.IsNullOrEmpty(expectedExceptionMessage)
                                                                )
                                                            );
                                                        return foundCaughtExpectedException;
                                                    }
                                                    , needDrillDownInnerExceptions
                                                );
            }

            try
            {
                action();
            }
            catch (AggregateException aggregateException)
            {
                caughtException = aggregateException;
                if (caughtException.GetType() == expectedExceptionType)
                {
                    if
                        (
                            string
                                .Compare
                                    (
                                        expectedExceptionMessage
                                        , caughtException.Message
                                        , true
                                    ) == 0
                            ||
                            string.IsNullOrEmpty(expectedExceptionMessage)
                        )
                    {
                        caughtExpectedException = caughtException;
                        foundCaughtExpectedException = true;
                    }
                }
                if (!foundCaughtExpectedException)
                {
                    if (needDrillDownInnerExceptions)
                    {
                        if (caughtException.InnerException != null)
                        {
                            drillDownInnerExceptionProcess(caughtException.InnerException);
                            if (!foundCaughtExpectedException)
                            {
                                caughtExpectedException = null!;
                            }
                        }
                    }
                }
                if (!foundCaughtExpectedException)
                {
                    var innerExceptions = aggregateException.Flatten().InnerExceptions;
                    if (needDrillDownInnerExceptions)
                    {
                        foreach (var e in innerExceptions)
                        {
                            drillDownInnerExceptionProcess(e);
                            if (foundCaughtExpectedException)
                            {
                                break;
                            }
                        }
                    }
                    if (!foundCaughtExpectedException)
                    {
                        caughtExpectedException = null!;
                    }
                }
            }
            //catch (TExpectedException expectedException)
            //{
            //    caughtException = expectedException;
            //    caughtExpectedException = expectedException;
            //    drillDownInnerExceptionProcess(caughtExpectedException);
            //    if (!foundCaughtExpectedException)
            //    {
            //        caughtExpectedException = null!;
            //    }
            //}
            catch (Exception exception)
            {
                caughtException = exception;
                caughtExpectedException = exception;
                drillDownInnerExceptionProcess(caughtExpectedException);
                if (!foundCaughtExpectedException)
                {
                    caughtExpectedException = null!;
                }
            }

            if (caughtException == null)
            {
                Assert
                    .Fail
                        (
                            $@"Expected exception of type ""{expectedExceptionType}"" but no exception was thrown."
                        );
            }
            else
            {
                Assert
                    .IsTrue
                        (
                            foundCaughtExpectedException
                            , $@"Expected exception of type ""{expectedExceptionType}"" but type of ""{caughtException.GetType()}"" was thrown instead.
The caught actual exception as below:
{_beginSpliterLineOfMessageBlock}
{caughtException}
{_endSpliterLineOfMessageBlock}
"
                        );
                processExpectedExceptionMessage(caughtExpectedException, expectedExceptionMessage);
                onProcessAction?.Invoke(caughtExpectedException);
            }
        }
    }
}
#endif